Workbook

Sheet Rozpocet
A1: Rozpocet - Svatba Paprckovi 29. 8. 2026
A2: MAX 100 000 Kc hard cap. Zmena ceny -> najit kompenzaci jinde. Modry text = editovatelny vstup.
A4: ID | B4: Termin | C4: Ukol | D4: Kdo | E4: Kategorie | F4: Plan (Kc) | G4: Skutecnost (Kc) | H4: Stav | I4: Timestamp | J4: Poznamka
A5: 1 | B5: 2026-05-29 | C5: Termín konfirmace | D5: Mamka | E5: mandatory | F5: 0 | G5: 0 | H5: [x] | I5: 2026-05-20T14:30 | J5: Hotovo
A6: 2 | B6: 2026-05-29 | C6: Návštěva radnice (Nová radnice Ostrava) | D6: Mamka | E6: mandatory | F6: 0 | G6: 0 | H6: [x] | I6: 2026-05-20T14:30 | J6: Hotovo
A7: 3 | B7: 2026-05-29 | C7: Informování dětí | D7: Mamka | E7: mandatory | F7: 0 | G7: 0 | H7: [x] | I7: 2026-05-20T14:30 | J7: Hotovo
A8: 4 | B8: 2026-05-29 | C8: Svědci domluveni (Kikinka + Žanetka) | D8: Mamka | E8: mandatory | F8: 0 | G8: 0 | H8: [x] | I8: 2026-05-20T14:30 | J8: Hotovo
A9: 5 | B9: 2026-06-30 | C9: Domluva oddávajícího (11:15 Nová radnice) | D9: Mamka | E9: mandatory | F9: 0 | G9: 0 | H9: [x] | I9: 2026-05-20T14:30 | J9: Mamka
A10: 6 | B10: 2026-07-10 | C10: Svatební oznámení | D10: Mamka | E10: mandatory | F10: 1500 | H10: [ ]
A11: 7 | B11: 2026-07-15 | C11: Zlatá koliba - menu + catering | D11: Žanetka | E11: mandatory | F11: 30000 | H11: [ ] | J11: 30 lidí; polévka 95 Kč/os; druhé 275 Kč/os; oběd = 11 100 Kč (30×370); pití k obědu + chlast = zbytek do 30k; 21.5. návštěva u Miloše
A12: 8 | B12: 2026-07-15 | C12: Svatební šaty (Mamka) | D12: Mamka | E12: mandatory | F12: 12000 | H12: [ ] | J12: plán 11 100; budget cca 12 000; max 15 000 Kč
A13: 9 | B13: 2026-07-15 | C13: Oblek a sako (Taťka) | D13: Taťka | E13: mandatory | F13: 8000 | H13: [ ]
A14: 10 | B14: 2026-07-15 | C14: Prstýnky - nákup a úprava | D14: Taťka | E14: mandatory | F14: 20000 | H14: [ ]
A15: 11 | B15: 2026-07-15 | C15: Seznam hostů | D15: Mamka | E15: mandatory | F15: 0 | H15: [ ]
A16: 12 | B16: 2026-07-15 | C16: Svatební cesta - termín ubytování program | D16: Taťka | E16: optional | F16: 0 | H16: [ ]
A17: 13 | B17: 2026-08-01 | C17: Nápoje a bar | D17: Žanetka | E17: mandatory | F17: 6000 | H17: [ ]
A18: 14 | B18: 2026-08-01 | C18: Doplňky (boty šperky) | D18: Mamka | E18: mandatory | F18: 3000 | H18: [ ]
A19: 15 | B19: 2026-08-01 | C19: Ubytování pro hosty | D19: Žanetka | E19: mandatory | F19: 5000 | H19: [ ]
A20: 16 | B20: 2026-08-10 | C20: Dárky pro svědky | D20: Mamka | E20: important | F20: 500 | H20: [ ]
A21: 17 | B21: 2026-08-15 | C21: Dekorace a květiny na radnici | D21: Kikinka | E21: mandatory | F21: 3000 | H21: [ ]
A22: 18 | B22: 2026-08-15 | C22: Dekorace Zlaté koliby | D22: Děti | E22: important | F22: 1000 | H22: [ ] | J22: Výzdoba - role Dětí
A23: 19 | B23: 2026-08-15 | C23: Dárky pro rodiče a poděkování | D23: Taťka | E23: important | F23: 500 | H23: [ ]
A24: 20 | B24: 2026-08-15 | C24: První tanec | D24: Mamka | E24: important | F24: 0 | H24: [ ]
A25: 21 | B25: 2026-08-20 | C25: Doprava (radnice -> Zlatá koliba) | D25: Taťka | E25: mandatory | F25: 3000 | H25: [ ]
A26: 22 | B26: 2026-08-20 | C26: Svatební dort | D26: Děti, Mamka | E26: mandatory | F26: 3000 | H26: [ ] | J26: Dort - role Dětí
A27: 23 | B27: 2026-08-20 | C27: Oddávající podpisy doklady | D27: Kikinka | E27: mandatory | F27: 0 | H27: [ ]
A28: 24 | B28: 2026-08-20 | C28: Fotokoutek / selfie zóna | D28: Taťka | E28: important | F28: 1000 | H28: [ ]
A29: 25 | B29: 2026-08-20 | C29: Uvítací cedule | D29: Mamka | E29: important | F29: 0 | H29: [ ]
A30: 26 | B30: 2026-08-20 | C30: Dárky na přivítanou pro hosty | D30: Mamka | E30: important | F30: 0 | H30: [ ]
A31: 27 | B31: 2026-08-20 | C31: Hry pro hosty | D31: Žanetka | E31: important | F31: 0 | H31: [ ]
A32: 28 | B32: 2026-08-20 | C32: Playlist / hudba | D32: Taťka | E32: important | F32: 0 | H32: [ ]
A33: 29 | B33: 2026-08-20 | C33: Drobnosti pro hosty (guestbook + favory) | D33: Mamka | E33: optional | F33: 500 | H33: [ ]
A34: 30 | B34: 2026-08-25 | C34: Proslovy | D34: Kikinka | E34: important | F34: 0 | H34: [ ]
A35: 31 | B35: 2026-08-25 | C35: Líčení / nehty / vlasy (Mamka) | D35: Mamka | E35: important | F35: 1500 | H35: [ ]
A36: 32 | B36: 2026-08-25 | C36: Střih a úprava (Taťka) | D36: Taťka | E36: important | F36: 500 | H36: [ ]
A37: 33 | B37: 2026-08-25 | C37: Confetti a prskavky | D37: Žanetka | E37: optional | F37: 0 | H37: [ ]
A38: 34 | B38: 2026-08-25 | C38: Fotograf / dokumentace | D38: Děti | E38: optional | F38: 0 | H38: [ ] | J38: Focení - role Dětí
A39: 35 | B39: 2026-09-05 | C39: Změna příjmení (po svatbě) | D39: Mamka | E39: mandatory | F39: 0 | H39: [ ]
A40: 36 | B40: 2026-05-25 | C40: Schůzka - prstýnky (Dáda+Taťka+Žanetka) | D40: Dáda, Taťka, Žanetka | E40: important | F40: 0 | H40: [ ] | J40: výběr prstýnků dle Excelu
A42: SHRNUTI ROZPOCTU
...

Sheet Podle osoby
A1: Rozpocet podle osoby
A3: Osoba | B3: Pocet ukolu | C3: Plan (Kc) | D3: Skutecnost (Kc) | E3: Rozdil
A4: Mamka | B4: =COUNTIF(Rozpocet!D5:D40,"*"&A4&"*") | C4: =SUMIF(Rozpocet!D5:D40,"*"&A4&"*",Rozpocet!F5:F40) | D4: =SUMIF(Rozpocet!D5:D40,"*"&A4&"*",Rozpocet!G5:G40) | E4: =C4-D4
A5: Tatka | B5: =COUNTIF(Rozpocet!D5:D40,"*"&A5&"*") | C5: =SUMIF(Rozpocet!D5:D40,"*"&A5&"*",Rozpocet!F5:F40) | D5: =SUMIF(Rozpocet!D5:D40,"*"&A5&"*",Rozpocet!G5:G40) | E5: =C5-D5
A6: Zanetka | B6: =COUNTIF(Rozpocet!D5:D40,"*"&A6&"*") | C6: =SUMIF(Rozpocet!D5:D40,"*"&A6&"*",Rozpocet!F5:F40) | D6: =SUMIF(Rozpocet!D5:D40,"*"&A6&"*",Rozpocet!G5:G40) | E6: =C6-D6
A7: Kikinka | B7: =COUNTIF(Rozpocet!D5:D40,"*"&A7&"*") | C7: =SUMIF(Rozpocet!D5:D40,"*"&A7&"*",Rozpocet!F5:F40) | D7: =SUMIF(Rozpocet!D5:D40,"*"&A7&"*",Rozpocet!G5:G40) | E7: =C7-D7
A8: Deti | B8: =COUNTIF(Rozpocet!D5:D40,"*"&A8&"*") | C8: =SUMIF(Rozpocet!D5:D40,"*"&A8&"*",Rozpocet!F5:F40) | D8: =SUMIF(Rozpocet!D5:D40,"*"&A8&"*",Rozpocet!G5:G40) | E8: =C8-D8
A9: Dada | B9: =COUNTIF(Rozpocet!D5:D40,"*"&A9&"*") | C9: =SUMIF(Rozpocet!D5:D40,"*"&A9&"*",Rozpocet!F5:F40) | D9: =SUMIF(Rozpocet!D5:D40,"*"&A9&"*",Rozpocet!G5:G40) | E9: =C9-D9
